<?xml version="1.0" encoding="utf-8"?>
<!-- This URDF was automatically created by SolidWorks to URDF Exporter! Originally created by Stephen Brawner (brawner@gmail.com) 
     Commit Version: 1.5.1-0-g916b5db  Build Version: 1.5.7152.31018
     For more information, please see http://wiki.ros.org/sw_urdf_exporter -->
<robot
  name="ros_gbot_v6">
  <link
    name="base_link">
    <inertial>
      <origin
        xyz="0.000107131917263859 0.00653261870246687 0.0399577909370542"
        rpy="0 0 0" />
      <mass
        value="63.1573794570293" />
      <inertia
        ixx="4.67427118435729"
        ixy="-7.79726366169792E-06"
        ixz="2.63670806401243E-06"
        iyy="3.35001282811798"
        iyz="-5.73023731941114E-06"
        izz="5.19786414094806" />
    </inertial>
    <visual>
      <origin
        xyz="0 0 0"
        rpy="0 0 0" />
      <geometry>
        <mesh
          filename="package://ros_gbot_v6/meshes/base_link.STL" />
      </geometry>
      <material
        name="">
        <color
          rgba="0.866666666666667 0.866666666666667 0.890196078431372 1" />
      </material>
    </visual>
    <collision>
      <origin
        xyz="0 0 0"
        rpy="0 0 0" />
      <geometry>
        <mesh
          filename="package://ros_gbot_v6/meshes/base_link.STL" />
      </geometry>
    </collision>
  </link>
  <link
    name="rear_right_wheel">
    <inertial>
      <origin
        xyz="0.00224346422313693 0.101003613835054 2.62642884585329E-06"
        rpy="0 0 0" />
      <mass
        value="3.47663199758312" />
      <inertia
        ixx="0.0367535290092486"
        ixy="0.00070974747764749"
        ixz="1.22682866728318E-06"
        iyy="0.0687260180744422"
        iyz="-2.40294219137256E-08"
        izz="0.036737976536622" />
    </inertial>
    <visual>
      <origin
        xyz="0 0 0"
        rpy="0 0 0" />
      <geometry>
        <mesh
          filename="package://ros_gbot_v6/meshes/rear_right_wheel.STL" />
      </geometry>
      <material
        name="">
        <color
          rgba="0.792156862745098 0.819607843137255 0.933333333333333 1" />
      </material>
    </visual>
    <collision>
      <origin
        xyz="0 0 0"
        rpy="0 0 0" />
      <geometry>
        <mesh
          filename="package://ros_gbot_v6/meshes/rear_right_wheel.STL" />
      </geometry>
    </collision>
  </link>
  <joint
    name="joint_rear_right_wheel"
    type="continuous">
    <origin
      xyz="-0.502241040205355 -0.652744484435201 -0.52967315007608"
      rpy="0 0 0" />
    <parent
      link="base_link" />
    <child
      link="rear_right_wheel" />
    <axis
      xyz="0.0221822575349659 0.999753943453414 0" />
  </joint>
  <link
    name="front_right_wheel">
    <inertial>
      <origin
        xyz="0.00122855436743907 0.101021056186895 -3.1183313921046E-06"
        rpy="0 0 0" />
      <mass
        value="3.476632000292" />
      <inertia
        ixx="0.0367419544455524"
        ixy="0.000388610783470214"
        ixz="-1.04909330702559E-06"
        iyy="0.0687370464337502"
        iyz="1.02936328248315E-08"
        izz="0.0367385227412184" />
    </inertial>
    <visual>
      <origin
        xyz="0 0 0"
        rpy="0 0 0" />
      <geometry>
        <mesh
          filename="package://ros_gbot_v6/meshes/front_right_wheel.STL" />
      </geometry>
      <material
        name="">
        <color
          rgba="0.792156862745098 0.819607843137255 0.933333333333333 1" />
      </material>
    </visual>
    <collision>
      <origin
        xyz="0 0 0"
        rpy="0 0 0" />
      <geometry>
        <mesh
          filename="package://ros_gbot_v6/meshes/front_right_wheel.STL" />
      </geometry>
    </collision>
  </link>
  <joint
    name="joint_front_right_wheel"
    type="continuous">
    <origin
      xyz="0.49877319241294 -0.652761894210343 -0.516889258310441"
      rpy="0 0 0" />
    <parent
      link="base_link" />
    <child
      link="front_right_wheel" />
    <axis
      xyz="0.0121431832331468 0.999926268832341 0" />
  </joint>
  <link
    name="rear_left_wheel">
    <inertial>
      <origin
        xyz="-0.000343092461787098 -0.101027891160667 -2.56485047311905E-07"
        rpy="0 0 0" />
      <mass
        value="3.47663200040774" />
      <inertia
        ixx="0.0367394738669235"
        ixy="0.000109813063938178"
        ixz="-1.77061249540662E-07"
        iyy="0.0687413889708173"
        iyz="1.39867568241698E-09"
        izz="0.0367366607827925" />
    </inertial>
    <visual>
      <origin
        xyz="0 0 0"
        rpy="0 0 0" />
      <geometry>
        <mesh
          filename="package://ros_gbot_v6/meshes/rear_left_wheel.STL" />
      </geometry>
      <material
        name="">
        <color
          rgba="0.792156862745098 0.819607843137255 0.933333333333333 1" />
      </material>
    </visual>
    <collision>
      <origin
        xyz="0 0 0"
        rpy="0 0 0" />
      <geometry>
        <mesh
          filename="package://ros_gbot_v6/meshes/rear_left_wheel.STL" />
      </geometry>
    </collision>
  </link>
  <joint
    name="joint_rear_left_wheel"
    type="continuous">
    <origin
      xyz="-0.499653342478264 0.666065578722078 -0.533450899227477"
      rpy="0 0 0" />
    <parent
      link="base_link" />
    <child
      link="rear_left_wheel" />
    <axis
      xyz="0.00343128446693173 0.999994113126126 0" />
  </joint>
  <link
    name="front_left_wheel">
    <inertial>
      <origin
        xyz="0.000645618781741408 -0.101026463468935 7.90162408947914E-07"
        rpy="0 0 0" />
      <mass
        value="3.47663200030706" />
      <inertia
        ixx="0.0367402820725434"
        ixy="-0.000203407742449012"
        ixz="5.3153180530456E-07"
        iyy="0.0687404728849979"
        iyz="3.64129124124682E-09"
        izz="0.0367367686629771" />
    </inertial>
    <visual>
      <origin
        xyz="0 0 0"
        rpy="0 0 0" />
      <geometry>
        <mesh
          filename="package://ros_gbot_v6/meshes/front_left_wheel.STL" />
      </geometry>
      <material
        name="">
        <color
          rgba="0.792156862745098 0.819607843137255 0.933333333333333 1" />
      </material>
    </visual>
    <collision>
      <origin
        xyz="0 0 0"
        rpy="0 0 0" />
      <geometry>
        <mesh
          filename="package://ros_gbot_v6/meshes/front_left_wheel.STL" />
      </geometry>
    </collision>
  </link>
  <joint
    name="joint_front_left_wheel"
    type="continuous">
    <origin
      xyz="0.499357867042557 0.666064132757828 -0.546889258311313"
      rpy="0 0 0" />
    <parent
      link="base_link" />
    <child
      link="front_left_wheel" />
    <axis
      xyz="0.00635595854141834 0.999979800691504 0" />
  </joint>
  <link
    name="camera_link">
    <inertial>
      <origin
        xyz="-0.0280078070877298 7.05875971007686E-08 0.000670749747477606"
        rpy="0 0 0" />
      <mass
        value="0.0672687145287375" />
      <inertia
        ixx="1.99056626902582E-05"
        ixy="5.52701962816837E-12"
        ixz="1.54307576079351E-07"
        iyy="1.85006153122466E-05"
        iyz="-9.12169393956435E-11"
        izz="1.75366184056671E-05" />
    </inertial>
    <visual>
      <origin
        xyz="0 0 0"
        rpy="0 0 0" />
      <geometry>
        <mesh
          filename="package://ros_gbot_v6/meshes/camera_link.STL" />
      </geometry>
      <material
        name="">
        <color
          rgba="0.941176470588235 0.96078431372549 0.968627450980392 0.7" />
      </material>
    </visual>
    <collision>
      <origin
        xyz="0 0 0"
        rpy="0 0 0" />
      <geometry>
        <mesh
          filename="package://ros_gbot_v6/meshes/camera_link.STL" />
      </geometry>
    </collision>
  </link>
  <joint
    name="joint_camera_link"
    type="fixed">
    <origin
      xyz="0 -0.0316300000000004 -0.0563499999999992"
      rpy="0 0 -1.5707963267949" />
    <parent
      link="base_link" />
    <child
      link="camera_link" />
    <axis
      xyz="0 0 0" />
  </joint>
<gazebo reference="rear_right_wheel">
    <material>Gazebo/DarkGrey</material>
</gazebo>
<gazebo reference="rear_left_wheel">
    <material>Gazebo/DarkGrey</material>
</gazebo>
<gazebo reference="front_right_wheel">
    <material>Gazebo/DarkGrey</material>
</gazebo>
<gazebo reference="front_left_wheel">
    <material>Gazebo/DarkGrey</material>
</gazebo>
<gazebo reference="base_link">
    <material>Gazebo/GreenFlat</material>
</gazebo>
<gazebo>
  <plugin name="skid_steer_drive_controller" filename="libgazebo_ros_skid_steer_drive.so">
    <updateRate>100.0</updateRate>
    <leftFrontJoint>joint_front_left_wheel</leftFrontJoint>
    <rightFrontJoint>joint_front_right_wheel</rightFrontJoint>
    <leftRearJoint>joint_rear_left_wheel</leftRearJoint>
    <rightRearJoint>joint_rear_right_wheel</rightRearJoint>
    <wheelSeparation>2</wheelSeparation>
    <wheelDiameter>0.60</wheelDiameter>
    <robotBaseFrame>base_link</robotBaseFrame>
    <MaxForce>150.0</MaxForce>
    <torque>150</torque>
    <commandTopic>cmd_vel</commandTopic>
    <odometryTopic>odom</odometryTopic>
    <odometryFrame>odom</odometryFrame>
    <broadcastTF>1</broadcastTF>
  </plugin>
</gazebo>
<gazebo reference="camera_link">
    <sensor type="camera" name="cv_camera">
      <update_rate>5.0</update_rate>
      <camera name="head">
        <horizontal_fov>1.3962634</horizontal_fov>
        <image>
          <width>800</width>
          <height>800</height>
          <format>R8G8B8</format>
        </image>
        <clip>
          <near>0.02</near>
          <far>300</far>
        </clip>
        <noise>
          <type>gaussian</type>
          <!-- Noise is sampled independently per pixel on each frame.
               That pixel's noise value is added to each of its color
               channels, which at that point lie in the range [0,1]. -->
          <mean>0.0</mean>
          <stddev>0.007</stddev>
        </noise>
      </camera>
      <plugin name="camera_controller" filename="libgazebo_ros_camera.so">
        <alwaysOn>true</alwaysOn>
        <updateRate>0.0</updateRate>
        <cameraName>cv_camera</cameraName>
        <imageTopicName>image_raw</imageTopicName>
        <cameraInfoTopicName>camera_info</cameraInfoTopicName>
        <frameName>camera_link</frameName>
        <hackBaseline>0.07</hackBaseline>
        <distortionK1>0.0</distortionK1>
        <distortionK2>0.0</distortionK2>
        <distortionK3>0.0</distortionK3>
        <distortionT1>0.0</distortionT1>
        <distortionT2>0.0</distortionT2>
      </plugin>
    </sensor>
</gazebo>
</robot>